<mujoco>
    
    <!-- <option gravity="0 0 0" /> -->

    <default>

        <default class="group1">
            <geom group="1" />
            <joint group="1" />

            <default class="limbs">

                <default class="Spine">
                    <geom mass="0.001" type="box" size="0.005 0.045 0.025" rgba="0.4 0.7 1.0 1" group="1"/>
                </default>

                <default class="SpineConnector">
                    <geom type="sphere" size="0.005" group="1"/>
                </default>

                <default class="Limb">
                    <geom mass="1.5" type="box" size="0.08 0.045 0.025" rgba="0.4 0.7 1.0 1" group="1"/>
                </default>

                <default class="AbductionGeom">
                    <geom type="capsule" mass="0.001" size="0.01" rgba="0.0 0.5 0.0 1" group="1"/>
                </default>

                <default class="UpLeg">
                    <geom type="capsule" mass="0.05" size="0.01" fromto="0 0 0 -0.14 0 0" rgba="0.0 0.5 0.0 1" group="1"/>
                </default>

                <default class="DownLeg">
                    <geom type="capsule" mass="0.05" size="0.01" fromto="0 0 0 0.14 0 0" rgba="0.0 0.5 0.0 1" group="1"/>
                </default>

                <default class="Foot">
                    <geom type="sphere" mass="0.001" size="0.02" rgba="1.0 1.0 0.1 1" friction="2 0.02 0.01" group="1"/>
                </default>

            </default>

            <default class="joints">

                <default class="spine-z-joint">
                    <joint limited="true" range="-12 12" type="hinge" 
                        stiffness="0" damping="0.1" armature="0.0065"
                        />
                </default>

                <default class="spine-y-joint">
                    <joint limited="true" range="-12 12" type="hinge" 
                        axis="0 1 0" stiffness="0" damping="0.1" armature="0.0065" />
                </default>

                <default class="abduction_joint">
                    <joint limited="true" range="-20 20" type="hinge" 
                        axis="1 0 0" stiffness="0" damping="0.1" armature="0.0065" />
                </default>

                <default class="hip_joint">
                    <joint limited="true" range="-40 40" type="hinge" 
                        axis="0 1 0" stiffness="0" damping="0.1" armature="0.0065" />
                </default>

                <default class="knee_joint">
                    <joint limited="true" range="-30 30" type="hinge" 
                        axis="0 1 0" stiffness="0" damping="0.1" armature="0.0065" />
                </default>

            </default>
        </default>


    </default>

    <worldbody>
        <body name="main_body" pos="0 0 0.2" euler="0 0 0" childclass="group1">

            
            <joint name="rail" type="free"/>
            
            <geom name="Frontlimb" class="Limb"/>
            
            <site name="head" pos="0.1 0 0" size="0.02"/>

            <body name="FL" pos="0.03 0.045 0">
                <body name="LegFrame_FL">
                    <joint name="AbductionJoint_FL" class="abduction_joint"/>
                    <geom name="Abduction_FL" class="AbductionGeom" fromto="0 0 0 0 0.05 0"/>

                    <body name="UpLegFrame_FL" pos="0 0.05 0" euler="0 -45 0">
                        <joint name="HipJoint_FL" class="hip_joint" />
                        <geom name="UpLeg_FL" class="UpLeg"/>
        
                        <body name="DownLegFrame_FL" pos="-0.14 0 0" euler="0 90 0">
                            <joint name="KneeJoint_FL" class="knee_joint" />
                            <geom name="DownLeg_FL" class="DownLeg"/>
        
                            <body name="FootFrame_FL" pos="0.14 0 0">
                                <geom name="Foot_FL" class="Foot"/>
                                <site name="Foot_FL_contact" size="0.021"/>
                            </body>
                        </body>
                    </body>
                </body>        
            </body>

            <body name="FR" pos="0.03 -0.045 0">
                <body name="LegFrame_FR">
                    <joint name="AbductionJoint_FR" class="abduction_joint"/>
                    <geom name="Abduction_FR" class="AbductionGeom" fromto="0 0 0 0 -0.05 0"/>

                    <body name="UpLegFrame_FR" pos="0 -0.05 0" euler="0 -45 0">
                        <joint name="HipJoint_FR" class="hip_joint" />
                        <geom name="UpLeg_FR" class="UpLeg"/>
        
                        <body name="DownLegFrame_FR" pos="-0.14 0 0" euler="0 90 0">
                            <joint name="KneeJoint_FR" class="knee_joint"/>
                            <geom name="DownLeg_FR" class="DownLeg"/>
        
                            <body name="FootFrame_FR" pos="0.14 0 0">
                                <geom name="Foot_FR" class="Foot"/>
                                <site name="Foot_FR_contact" size="0.021"/>
                            </body>
                        </body>
                    </body>
                </body>
            </body>

            <body name="T1" pos="-0.085 0 0">

                <joint name="Spine1-Y" class="spine-y-joint"/>
                <joint name="Spine1-Z" class="spine-z-joint"/>

                <geom name="T1-Connector" class="SpineConnector"/>
                <geom name="T1" class="Spine" pos="-0.01 0 0"/>

                <body name="T2" pos="-0.02 0 0">

                    <joint name="Spine2-Y" class="spine-y-joint"/>
                    <joint name="Spine2-Z" class="spine-z-joint"/>
    
                    <geom name="T2-Connector" class="SpineConnector"/>
                    <geom name="T2" class="Spine" pos="-0.01 0 0"/>    

                    <body name="COM" pos="-0.01 0 0"></body>
                    
                    <body name="T3" pos="-0.02 0 0">

                        <joint name="Spine3-Y" class="spine-y-joint"/>
                        <joint name="Spine3-Z" class="spine-z-joint"/>
        
                        <geom name="T3-Connector" class="SpineConnector"/>
                        <geom name="T3" class="Spine" pos="-0.01 0 0"/>    
    
                        <body name="Hindlimb" pos="-0.02 0 0">

                            <joint name="Hip-Y" class="spine-y-joint"/>
                            <joint name="Hip-Z" class="spine-z-joint"/>    

                            <geom name="Hip-Connector" class="SpineConnector"/>
                            <geom name="HindLimb" class="Limb" pos="-0.085 0 0"/>    

                            <body name="RL" pos="-0.12 0.044 0">
                                <body name="LegFrame_RL">
                                    <joint name="AbductionJoint_RL" class="abduction_joint"/>
                                    <geom name="Abduction_RL" class="AbductionGeom" fromto="0 0 0 0 0.05 0"/>
                
                                    <body name="UpLegFrame_RL" pos="0 0.05 0" euler="0 -45 0">
                                        <joint name="HipJoint_RL" class="hip_joint" />
                                        <geom name="UpLeg_RL" class="UpLeg"/>
                        
                                        <body name="DownLegFrame_RL" pos="-0.14 0 0" euler="0 90 0">
                                            <joint name="KneeJoint_RL" class="knee_joint" />
                                            <geom name="DownLeg_RL" class="DownLeg"/>
                        
                                            <body name="FootFrame_RL" pos="0.14 0 0">
                                                <geom name="Foot_RL" class="Foot"/>
                                                <site name="Foot_RL_contact" size="0.021"/>
                                            </body>
                                        </body>
                                    </body>
                                </body>
                            </body>
        
                            <body name="RR" pos="-0.12 -0.044 0">
                                <body name="LegFrame_RR">
                                    <joint name="AbductionJoint_RR" class="abduction_joint"/>
                                    <geom name="Abduction_RR" class="AbductionGeom" fromto="0 0 0 0 -0.05 0"/>
                                    
                                    <body name="UpLegFrame_RR" pos="0 -0.05 0" euler="0 -45 0">
                                        <joint name="HipJoint_RR" class="hip_joint" />
                                        <geom name="UpLeg_RR" class="UpLeg"/>
                        
                                        <body name="DownLegFrame_RR" pos="-0.14 0 0" euler="0 90 0">
                                            <joint name="KneeJoint_RR" class="knee_joint" />
                                            <geom name="DownLeg_RR" class="DownLeg"/>
                        
                                            <body name="FootFrame_RR" pos="0.14 0 0">
                                                <geom name="Foot_RR" class="Foot"/>
                                                <site name="Foot_RR_contact" size="0.021"/>
                                            </body>
                                        </body>
                                    </body>
                                </body>
                            </body>
                        </body>
                    </body>
                </body>
            </body>
        </body>
    </worldbody>
</mujoco>
